{"uuid": "d1cb6d23-9c48-4edb-87d5-73645f2bc25b", "children": ["0f102219-ad8a-42d7-9b82-4f9169a92918", "0a76d8dd-45bc-481b-811d-aefb67508bad", "1c0c19fa-e8e5-4a17-aa5c-5ef6ea175f8d", "add0d0f2-06cc-4fea-bc8d-b2be430fcfe5", "655da846-f71d-4f46-8352-12bb5f2b6cad", "c022f030-71b2-4661-b5a7-f556115dbc60"], "befores": [{"name": "_Class__pytest_setup_class", "status": "broken", "statusDetails": {"message": "KeyError: 'user_id'\n", "trace": "  File \"D:\\Python\\Python37\\lib\\site-packages\\pluggy\\callers.py\", line 187, in _multicall\n    res = hook_impl.function(*args)\n  File \"D:\\Python\\Python37\\lib\\site-packages\\_pytest\\fixtures.py\", line 964, in pytest_fixture_setup\n    result = call_fixture_func(fixturefunc, request, kwargs)\n  File \"D:\\Python\\Python37\\lib\\site-packages\\_pytest\\fixtures.py\", line 788, in call_fixture_func\n    res = next(it)\n  File \"D:\\Python\\Python37\\lib\\site-packages\\_pytest\\python.py\", line 701, in xunit_setup_class_fixture\n    _call_with_optional_argument(func, self.obj)\n  File \"D:\\Python\\Python37\\lib\\site-packages\\_pytest\\python.py\", line 632, in _call_with_optional_argument\n    func(arg)\n  File \"E:\\study\\python\\autotest\\testcases\\exception_testing\\test_api_exception_case.py\", line 25, in setup_class\n    self.sd = SendRequest()\n  File \"E:\\study\\python\\autotest\\common\\base_utils\\Request.py\", line 14, in __init__\n    self.applet_res = Applet_Login().applogin(create_phone())\n  File \"E:\\study\\python\\autotest\\common\\login\\applet_login.py\", line 23, in applogin\n    self.Guid = result['Data']['user_id']\n"}, "start": 1594631306348, "stop": 1594631306859}], "start": 1594631306348, "stop": 1594631307080}